Workbook

Sheet Matriz de Manufatura
E2: Custo | F2: Tempo | G2: Soldabilidade/Facilidade de união | O2: 2 | P2: 3 | Q2: 5
D3: Weighted Rating | E3: 30 | F3: 35 | G3: 35 | H3: =SUM(E3:G3) -> 100 | J3: Melhor Processo Geral: | K3: =INDEX(B4:B29,MATCH(LARGE(H4:H29,1),H4:H29,0)) & " " & INDEX(C4:C29,MATCH(LARGE(H4:H29,1),H4:H29,0)) -> Fibra de Carbono (Manual/Infusion) Autoclave | L3: =LARGE(H4:H29,1) -> 360.02043 | O3: 2 | P3: 3 | Q3: 4 | R3: =SUMPRODUCT(O2:O3,P2:P3,Q2:Q3) -> 54
B4: Fibra de Carbono (Manual/Manual) | C4: Temperatura Ambiente | D4: Rating | E4: =(SMALL('Planilha de Dados'!D$3:D$28,1)/'Planilha de Dados'!D3)*4+1 -> 1.2737508 | F4: =(SMALL('Planilha de Dados'!E$3:E$28,1)/'Planilha de Dados'!E3)*4+1 -> 1.5128205 | G4: =('Planilha de Dados'!F3/LARGE('Planilha de Dados'!F$3:F$28,1))*4+1 -> 4.2 | H4: =SUM($E$3*E4,$F$3*F4,$G$3*G4) -> 238.16124
B5: Fibra de Carbono (Manual/Manual) | C5: Forno | D5: Rating | E5: =(SMALL('Planilha de Dados'!D$3:D$28,1)/'Planilha de Dados'!D4)*4+1 -> 1.2718987 | F5: =(SMALL('Planilha de Dados'!E$3:E$28,1)/'Planilha de Dados'!E4)*4+1 -> 3.5641026 | G5: =('Planilha de Dados'!F4/LARGE('Planilha de Dados'!F$3:F$28,1))*4+1 -> 4.2 | H5: =SUM($E$3*E5,$F$3*F5,$G$3*G5) -> 309.90055
B6: Fibra de Carbono (Manual/Manual) | C6: Autoclave | D6: Rating | E6: =(SMALL('Planilha de Dados'!D$3:D$28,1)/'Planilha de Dados'!D5)*4+1 -> 1.2664898 | F6: =(SMALL('Planilha de Dados'!E$3:E$28,1)/'Planilha de Dados'!E5)*4+1 -> 4.0769231 | G6: =('Planilha de Dados'!F5/LARGE('Planilha de Dados'!F$3:F$28,1))*4+1 -> 4.2 | H6: =SUM($E$3*E6,$F$3*F6,$G$3*G6) -> 327.687 | O6: 4 | P6: 6
B7: Fibra de Carbono (Manual/Infusion) | C7: Temperatura Ambiente | D7: Rating | E7: =(SMALL('Planilha de Dados'!D$3:D$28,1)/'Planilha de Dados'!D6)*4+1 -> 1.2746561 | F7: =(SMALL('Planilha de Dados'!E$3:E$28,1)/'Planilha de Dados'!E6)*4+1 -> 1.6666667 | G7: =('Planilha de Dados'!F6/LARGE('Planilha de Dados'!F$3:F$28,1))*4+1 -> 4.2 | H7: =SUM($E$3*E7,$F$3*F7,$G$3*G7) -> 243.57302 | J7: Fibra de Carbono: | K7: =INDEX($B$4:$B$29,MATCH(L7,$H$4:$H$29,0)) & " " & INDEX($C$4:$C$29,MATCH(L7,$H$4:$H$29,0)) -> Fibra de Carbono (Manual/Infusion) Autoclave | L7: =LARGE(H4:H9,1) -> 360.02043 | O7: 2 | P7: 3 | R7: =SUMPRODUCT(O6:O7,P6:P7) -> 30
B8: Fibra de Carbono (Manual/Infusion) | C8: Forno | D8: Rating | E8: =(SMALL('Planilha de Dados'!D$3:D$28,1)/'Planilha de Dados'!D7)*4+1 -> 1.2727918 | F8: =(SMALL('Planilha de Dados'!E$3:E$28,1)/'Planilha de Dados'!E7)*4+1 -> 4.3333333 | G8: =('Planilha de Dados'!F7/LARGE('Planilha de Dados'!F$3:F$28,1))*4+1 -> 4.2 | H8: =SUM($E$3*E8,$F$3*F8,$G$3*G8) -> 336.85042 | J8: Fibra de Vidro: | K8: =INDEX($B$4:$B$29,MATCH(L8,$H$4:$H$29,0)) & " " & INDEX($C$4:$C$29,MATCH(L8,$H$4:$H$29,0)) -> Fibra de Vidro (Manual/Infusion) Autoclave | L8: =LARGE(H10:H15,1) -> 356.98402
B9: Fibra de Carbono (Manual/Infusion) | C9: Autoclave | D9: Rating | E9: =(SMALL('Planilha de Dados'!D$3:D$28,1)/'Planilha de Dados'!D8)*4+1 -> 1.2673476 | F9: =(SMALL('Planilha de Dados'!E$3:E$28,1)/'Planilha de Dados'!E8)*4+1 -> 5 | G9: =('Planilha de Dados'!F8/LARGE('Planilha de Dados'!F$3:F$28,1))*4+1 -> 4.2 | H9: =SUM($E$3*E9,$F$3*F9,$G$3*G9) -> 360.02043 | J9: Aramida: | K9: =INDEX($B$4:$B$29,MATCH(L9,$H$4:$H$29,0)) & " " & INDEX($C$4:$C$29,MATCH(L9,$H$4:$H$29,0)) -> Aramida(Manual/Infusion) Autoclave | L9: =LARGE(H16:H21,1) -> 330.09411 | N9: Metais | S9: Geral
B10: Fibra de Vidro (Manual/Manual) | C10: Temperatura Ambiente | D10: Rating | E10: =(SMALL('Planilha de Dados'!D$3:D$28,1)/'Planilha de Dados'!D9)*4+1 -> 1.1685846 | F10: =(SMALL('Planilha de Dados'!E$3:E$28,1)/'Planilha de Dados'!E9)*4+1 -> 1.5128205 | G10: =('Planilha de Dados'!F9/LARGE('Planilha de Dados'!F$3:F$28,1))*4+1 -> 4.2 | H10: =SUM($E$3*E10,$F$3*F10,$G$3*G10) -> 235.00626 | J10: Aluminio chassi | K10: =INDEX($B$4:$B$29,MATCH(L10,$H$4:$H$29,0)) & " " & INDEX($C$4:$C$29,MATCH(L10,$H$4:$H$29,0)) -> Aluminio Chassi Corte a agua + solda | L10: =H22 -> 304 | O10: Custo | P10: Tempo | Q10: Soldabilidade | R10: Total | T10: Custo | U10: Tempo | V10: Total
B11: Fibra de Vidro (Manual/Manual) | C11: Forno | D11: Rating | E11: =(SMALL('Planilha de Dados'!D$3:D$28,1)/'Planilha de Dados'!D10)*4+1 -> 1.1678803 | F11: =(SMALL('Planilha de Dados'!E$3:E$28,1)/'Planilha de Dados'!E10)*4+1 -> 3.5641026 | G11: =('Planilha de Dados'!F10/LARGE('Planilha de Dados'!F$3:F$28,1))*4+1 -> 4.2 | H11: =SUM($E$3*E11,$F$3*F11,$G$3*G11) -> 306.78 | J11: Aço 1020: | K11: =INDEX($B$4:$B$29,MATCH(L11,$H$4:$H$29,0)) & " " & INDEX($C$4:$C$29,MATCH(L11,$H$4:$H$29,0)) -> Aço 1020 Tubing Lasercut + weld + weld point | L11: =H23 -> 355.65765 | N11: Peso | O11: 30 | P11: 35 | Q11: 35 | R11: =SUM(O11:Q11) -> 100 | S11: Peso | T11: 55 | U11: 45 | V11: =SUM(T11:U11) -> 100
B12: Fibra de Vidro (Manual/Manual) | C12: Autoclave | D12: Rating | E12: =(SMALL('Planilha de Dados'!D$3:D$28,1)/'Planilha de Dados'!D11)*4+1 -> 1.1658025 | F12: =(SMALL('Planilha de Dados'!E$3:E$28,1)/'Planilha de Dados'!E11)*4+1 -> 4.0769231 | G12: =('Planilha de Dados'!F11/LARGE('Planilha de Dados'!F$3:F$28,1))*4+1 -> 4.2 | H12: =SUM($E$3*E12,$F$3*F12,$G$3*G12) -> 324.66638 | J12: Aço 4340: | K12: Aço 4340 Tubing Lasercut + weld + weld point | L12: =H24 -> 355.65765
B13: Fibra de Vidro (Manual/Infusion) | C13: Temperatura Ambiente | D13: Rating | E13: =(SMALL('Planilha de Dados'!D$3:D$28,1)/'Planilha de Dados'!D12)*4+1 -> 1.1689504 | F13: =(SMALL('Planilha de Dados'!E$3:E$28,1)/'Planilha de Dados'!E12)*4+1 -> 1.6666667 | G13: =('Planilha de Dados'!F12/LARGE('Planilha de Dados'!F$3:F$28,1))*4+1 -> 4.2 | H13: =SUM($E$3*E13,$F$3*F13,$G$3*G13) -> 240.40184 | J13: Aço 4130: | K13: Aço 4130 Tubing Lasercut + weld + weld point | L13: =H25 -> 355.65765
B14: Fibra de Vidro (Manual/Infusion) | C14: Forno | D14: Rating | E14: =(SMALL('Planilha de Dados'!D$3:D$28,1)/'Planilha de Dados'!D13)*4+1 -> 1.1682431 | F14: =(SMALL('Planilha de Dados'!E$3:E$28,1)/'Planilha de Dados'!E13)*4+1 -> 4.3333333 | G14: =('Planilha de Dados'!F13/LARGE('Planilha de Dados'!F$3:F$28,1))*4+1 -> 4.2 | H14: =SUM($E$3*E14,$F$3*F14,$G$3*G14) -> 333.71396 | J14: Aço 1010: | K14: Aço 1010 Tubing Lasercut + weld + weld point | L14: =H26 -> 355.65765
B15: Fibra de Vidro (Manual/Infusion) | C15: Autoclave | D15: Rating | E15: =(SMALL('Planilha de Dados'!D$3:D$28,1)/'Planilha de Dados'!D14)*4+1 -> 1.1661342 | F15: =(SMALL('Planilha de Dados'!E$3:E$28,1)/'Planilha de Dados'!E14)*4+1 -> 5 | G15: =('Planilha de Dados'!F14/LARGE('Planilha de Dados'!F$3:F$28,1))*4+1 -> 4.2 | H15: =SUM($E$3*E15,$F$3*F15,$G$3*G15) -> 356.98402 | J15: Titanio: | K15: =INDEX($B$4:$B$29,MATCH(L15,$H$4:$H$29,0)) & " " & INDEX($C$4:$C$29,MATCH(L15,$H$4:$H$29,0)) -> Titanio Tubing Lasercut + weld + weld point | L15: =H27 -> 220.89186
B16: Aramida (Manual/Manual) | C16: Temperatura Ambiente | D16: Rating | E16: =(SMALL('Planilha de Dados'!D$3:D$28,1)/'Planilha de Dados'!D15)*4+1 -> 1.2068127 | F16: =(SMALL('Planilha de Dados'!E$3:E$28,1)/'Planilha de Dados'!E15)*4+1 -> 1.5128205 | G16: =('Planilha de Dados'!F15/LARGE('Planilha de Dados'!F$3:F$28,1))*4+1 -> 3.4 | H16: =SUM($E$3*E16,$F$3*F16,$G$3*G16) -> 208.1531 | J16: Aluminio: | K16: =INDEX($B$4:$B$29,MATCH(L16,$H$4:$H$29,0)) & " " & INDEX($C$4:$C$29,MATCH(L16,$H$4:$H$29,0)) -> Alumínio Tubing Lasercut + weld + weld point | L16: =H28 -> 262.05206
B17: Aramida (Manual/Manual) | C17: Forno | D17: Rating | E17: =(SMALL('Planilha de Dados'!D$3:D$28,1)/'Planilha de Dados'!D16)*4+1 -> 1.2057539 | F17: =(SMALL('Planilha de Dados'!E$3:E$28,1)/'Planilha de Dados'!E16)*4+1 -> 3.5641026 | G17: =('Planilha de Dados'!F16/LARGE('Planilha de Dados'!F$3:F$28,1))*4+1 -> 3.4 | H17: =SUM($E$3*E17,$F$3*F17,$G$3*G17) -> 279.91621 | J17: Aço inox: | K17: =INDEX($B$4:$B$29,MATCH(L17,$H$4:$H$29,0)) & " " & INDEX($C$4:$C$29,MATCH(L17,$H$4:$H$29,0)) -> Aço inox Tubing Lasercut + weld + weld point | L17: =H29 -> 293.05358
B18: Aramida (Manual/Manual) | C18: Autoclave | D18: Rating | E18: =(SMALL('Planilha de Dados'!D$3:D$28,1)/'Planilha de Dados'!D17)*4+1 -> 1.2026415 | F18: =(SMALL('Planilha de Dados'!E$3:E$28,1)/'Planilha de Dados'!E17)*4+1 -> 4.0769231 | G18: =('Planilha de Dados'!F17/LARGE('Planilha de Dados'!F$3:F$28,1))*4+1 -> 3.4 | H18: =SUM($E$3*E18,$F$3*F18,$G$3*G18) -> 297.77155
B19: Aramida(Manual/Infusion) | C19: Temperatura Ambiente | D19: Rating | E19: =(SMALL('Planilha de Dados'!D$3:D$28,1)/'Planilha de Dados'!D18)*4+1 -> 1.207329 | F19: =(SMALL('Planilha de Dados'!E$3:E$28,1)/'Planilha de Dados'!E18)*4+1 -> 1.6666667 | G19: =('Planilha de Dados'!F18/LARGE('Planilha de Dados'!F$3:F$28,1))*4+1 -> 3.4 | H19: =SUM($E$3*E19,$F$3*F19,$G$3*G19) -> 213.5532
B20: Aramida(Manual/Infusion) | C20: Forno | D20: Rating | E20: =(SMALL('Planilha de Dados'!D$3:D$28,1)/'Planilha de Dados'!D19)*4+1 -> 1.2062649 | F20: =(SMALL('Planilha de Dados'!E$3:E$28,1)/'Planilha de Dados'!E19)*4+1 -> 4.3333333 | G20: =('Planilha de Dados'!F19/LARGE('Planilha de Dados'!F$3:F$28,1))*4+1 -> 3.4 | H20: =SUM($E$3*E20,$F$3*F20,$G$3*G20) -> 306.85461
B21: Aramida(Manual/Infusion) | C21: Autoclave | D21: Rating | E21: =(SMALL('Planilha de Dados'!D$3:D$28,1)/'Planilha de Dados'!D20)*4+1 -> 1.2031371 | F21: =(SMALL('Planilha de Dados'!E$3:E$28,1)/'Planilha de Dados'!E20)*4+1 -> 5 | G21: =('Planilha de Dados'!F20/LARGE('Planilha de Dados'!F$3:F$28,1))*4+1 -> 3.4 | H21: =SUM($E$3*E21,$F$3*F21,$G$3*G21) -> 330.09411
B22: Aluminio Chassi | C22: Corte a agua + solda | D22: Rating | E22: =(SMALL('Planilha de Dados'!D$3:D$28,1)/'Planilha de Dados'!D21)*4+1 -> 5 | F22: =(SMALL('Planilha de Dados'!E$3:E$28,1)/'Planilha de Dados'!E21)*4+1 -> 1.8 | G22: =('Planilha de Dados'!F21/LARGE('Planilha de Dados'!F$3:F$28,1))*4+1 -> 2.6 | H22: =SUM($E$3*E22,$F$3*F22,$G$3*G22) -> 304
B23: Aço 1020 | C23: Tubing Lasercut + weld + weld point | D23: Rating | E23: =(SMALL('Planilha de Dados'!D$3:D$28,1)/'Planilha de Dados'!D22)*4+1 -> 4.1260884 | F23: =(SMALL('Planilha de Dados'!E$3:E$28,1)/'Planilha de Dados'!E22)*4+1 -> 1.625 | G23: =('Planilha de Dados'!F22/LARGE('Planilha de Dados'!F$3:F$28,1))*4+1 -> 5 | H23: =SUM($E$3*E23,$F$3*F23,$G$3*G23) -> 355.65765
B24: Aço 4340 | C24: Tubing Lasercut + weld + weld point | D24: Rating | E24: =(SMALL('Planilha de Dados'!D$3:D$28,1)/'Planilha de Dados'!D23)*4+1 -> 4.1260884 | F24: =(SMALL('Planilha de Dados'!E$3:E$28,1)/'Planilha de Dados'!E23)*4+1 -> 1.625 | G24: =('Planilha de Dados'!F23/LARGE('Planilha de Dados'!F$3:F$28,1))*4+1 -> 5 | H24: =SUM($E$3*E24,$F$3*F24,$G$3*G24) -> 355.65765
B25: Aço 4130 | C25: Tubing Lasercut + weld + weld point | D25: Rating | E25: =(SMALL('Planilha de Dados'!D$3:D$28,1)/'Planilha de Dados'!D24)*4+1 -> 4.1260884 | F25: =(SMALL('Planilha de Dados'!E$3:E$28,1)/'Planilha de Dados'!E24)*4+1 -> 1.625 | G25: =('Planilha de Dados'!F24/LARGE('Planilha de Dados'!F$3:F$28,1))*4+1 -> 5 | H25: =SUM($E$3*E25,$F$3*F25,$G$3*G25) -> 355.65765
B26: Aço 1010 | C26: Tubing Lasercut + weld + weld point | D26: Rating | E26: =(SMALL('Planilha de Dados'!D$3:D$28,1)/'Planilha de Dados'!D25)*4+1 -> 4.1260884 | F26: =(SMALL('Planilha de Dados'!E$3:E$28,1)/'Planilha de Dados'!E25)*4+1 -> 1.625 | G26: =('Planilha de Dados'!F25/LARGE('Planilha de Dados'!F$3:F$28,1))*4+1 -> 5 | H26: =SUM($E$3*E26,$F$3*F26,$G$3*G26) -> 355.65765
B27: Titanio | C27: Tubing Lasercut + weld + weld point | D27: Rating | E27: =(SMALL('Planilha de Dados'!D$3:D$28,1)/'Planilha de Dados'!D26)*4+1 -> 3.5999416 | F27: =(SMALL('Planilha de Dados'!E$3:E$28,1)/'Planilha de Dados'!E26)*4+1 -> 1.4255319 | G27: =('Planilha de Dados'!F26/LARGE('Planilha de Dados'!F$3:F$28,1))*4+1 -> 1.8 | H27: =SUM($E$3*E27,$F$3*F27,$G$3*G27) -> 220.89186
B28: Alumínio | C28: Tubing Lasercut + weld + weld point | D28: Rating | E28: =(SMALL('Planilha de Dados'!D$3:D$28,1)/'Planilha de Dados'!D27)*4+1 -> 3.9367781 | F28: =(SMALL('Planilha de Dados'!E$3:E$28,1)/'Planilha de Dados'!E27)*4+1 -> 1.5128205 | G28: =('Planilha de Dados'!F27/LARGE('Planilha de Dados'!F$3:F$28,1))*4+1 -> 2.6 | H28: =SUM($E$3*E28,$F$3*F28,$G$3*G28) -> 262.05206
B29: Aço inox | C29: Tubing Lasercut + weld + weld point | D29: Rating | E29: =(SMALL('Planilha de Dados'!D$3:D$28,1)/'Planilha de Dados'!D28)*4+1 -> 3.9059526 | F29: =(SMALL('Planilha de Dados'!E$3:E$28,1)/'Planilha de Dados'!E28)*4+1 -> 1.625 | G29: =('Planilha de Dados'!F28/LARGE('Planilha de Dados'!F$3:F$28,1))*4+1 -> 3.4 | H29: =SUM($E$3*E29,$F$3*F29,$G$3*G29) -> 293.05358

Sheet Planilha de Dados
C2: Critério | D2: Custo | E2: Tempo | F2: Soldabilidade | H2: Critério | I2: Quantitativo | J2: Fibra de Carbono | L2: Fibra de Vidro | N2: Aramida | P2: Alumínio | R2: Aço (1020) | T2: Aço (4340) | V2: Aço (4130) | X2: Aço (1010) | Z2: Titânio | AB2: Alumínio | AD2: Aço Inox
A3: Monocoque | B3: Fibra de Carbono (Manual/Manual) | C3: Cura temperatura ambiente | D3: 4551 | E3: 2340 | F3: 4 | H3: Performance | I3: Modulo de elasticidade | J3: 240 | L3: 70 | N3: 117 | P3: 114 | R3: 200 | T3: 205 | V3: 205 | X3: 200 | Z3: 105 | AB3: 114 | AD3: 193
C4: Cura em forno | D4: 4582 | E4: =E3/5 -> 468 | F4: 4 | H4: Durabilidade | I4: Limite de resistência a fadiga (Mpa) | J4: =0.8*J5 -> 880 | L4: =0.8*L5 -> 268 | N4: 783 | P4: 170 | R4: 275 | T4: 600 | V4: 480 | X4: 240 | Z4: 510 | AB4: 170 | AD4: 240
C5: Cura em autoclave | D5: 4675 | E5: =E3/6 -> 390 | F5: 4 | H5: Confiabilidade | I5: Tensão de escoamento (Mpa) | J5: 1100 | L5: 335 | N5: 972 | P5: 460 | R5: 350 | T5: 470 | V5: 435 | X5: 200 | Z5: 940 | AB5: 460 | AD5: 215
B6: Fibra de Carbono (Manual/Infusion) | C6: Cura temperatura ambiente | D6: 4536 | E6: 1800 | F6: 4 | H6: Manufatura | I6: Matriz de decisão | J6: ='Matriz de Manufatura'!L7 -> 360.02043 | L6: ='Matriz de Manufatura'!L8 -> 356.98402 | N6: ='Matriz de Manufatura'!L9 -> 330.09411 | P6: ='Matriz de Manufatura'!L10 -> 304 | R6: ='Matriz de Manufatura'!L11 -> 355.65765 | T6: ='Matriz de Manufatura'!L12 -> 355.65765 | V6: ='Matriz de Manufatura'!L13 -> 355.65765 | X6: ='Matriz de Manufatura'!L14 -> 355.65765 | Z6: ='Matriz de Manufatura'!L15 -> 220.89186 | AB6: ='Matriz de Manufatura'!L16 -> 262.05206 | AD6: ='Matriz de Manufatura'!L17 -> 293.05358
C7: Cura em forno | D7: 4567 | E7: =E6/5 -> 360 | F7: 4 | H7: Conhecimento da equipe | I7: Qualitativo | J7: 5 | L7: 5 | N7: 3 | P7: 5 | R7: 5 | T7: 3 | V7: 2 | X7: 5 | Z7: 1 | AB7: 5 | AD7: 2
C8: Cura em autoclave | D8: 4660 | E8: =E6/6 -> 300 | F8: 4 | H8: Peso | I8: Densidade (kg/m³) | J8: 1760 | L8: 2400 | N8: 1420 | P8: 2700 | R8: 7850 | T8: 7850 | V8: 7850 | X8: 7850 | Z8: 4500 | AB8: 2700 | AD8: 7850
B9: Fibra de Vidro (Manual/Manual) | C9: Cura temperatura ambiente | D9: 7390 | E9: 2340 | F9: 4 | I9: ESPECIFICIDADE | J9: Bidirectional Carbon Fiber Fabric – CCS-200 | L9: Fibra de Vidro AF-0012 | N9: Bidirectional Para-Aramid Fabric – 200 gsm | P9: 6061 (6061-T61, A97076) Aluminum | R9: Aço 1020 | Z9: Titânio Grau 5 (Ti-6Al-4V) | AB9: 6061 (6061-T61, A97076) Aluminum | AD9: AISI 304
C10: Cura em forno | D10: 7421 | E10: =E9/5 -> 468 | F10: 4
C11: Cura em autoclave | D11: 7514 | E11: =E9/6 -> 390 | F11: 4
B12: Fibra de Vidro (Manual/Infusion) | C12: Cura temperatura ambiente | D12: 7374 | E12: 1800 | F12: 4
C13: Cura em forno | D13: 7405 | E13: =E12/5 -> 360 | F13: 4
C14: Cura em autoclave | D14: 7499 | E14: =E12/6 -> 300 | F14: 4
B15: Aramida (Manual/Manual) | C15: Cura temperatura ambiente | D15: 6024 | E15: 2340 | F15: 3
C16: Cura em forno | D16: 6055 | E16: =E15/5 -> 468 | F16: 3
C17: Cura em autoclave | D17: 6148 | E17: =E15/6 -> 390 | F17: 3
B18: Aramida(Manual/Infusion) | C18: Cura temperatura ambiente | D18: 6009 | E18: 1800 | F18: 3
C19: Cura em forno | D19: 6040 | E19: =E18/5 -> 360 | F19: 3
C20: Cura em autoclave | D20: 6133 | E20: =E18/6 -> 300 | F20: 3
B21: Aluminio | C21: Corte a agua + solda | D21: 311.46 | E21: =25*60 -> 1500 | F21: 2
A22: Chassi tubular | B22: Aço 1020 | C22: Tubing Lasercut + weld + weld point | D22: 398.53 | E22: 1920 | F22: 5
B23: Aço 4340 | C23: Tubing Lasercut + weld + weld point | D23: 398.53 | E23: 1920 | F23: 5
B24: Aço 4130 | C24: Tubing Lasercut + weld + weld point | D24: 398.53 | E24: 1920 | F24: 5
B25: Aço 1010 | C25: Tubing Lasercut + weld + weld point | D25: 398.53 | E25: 1920 | F25: 5
B26: Titanio | C26: Tubing Lasercut + weld + weld point | D26: 479.18 | E26: 2820 | F26: 1
B27: Alumínio | C27: Tubing Lasercut + weld + weld point | D27: 424.22 | E27: 2340 | F27: 2
B28: Aço Inox | C28: Tubing Lasercut + weld + weld point | D28: 428.72 | E28: 1920 | F28: 3

Sheet Decision Matrix
B4: Decision Matrix
B7: Melhor Material por Classe | D7: Pontuação
B8: =INDEX(C14:H14,MATCH(D8,C22:H22,0)) -> Fibra de Carbono | D8: =LARGE(C22:H22,1) -> 495.34681
B9: =INDEX(J14:X14,MATCH(D9,J22:X22,0)) -> Aluminio CHASSI | D9: =LARGE(I22:X22,1) -> 308.82233
C12: MONOCOQUE
C13: Compósitos | K13: Metais
D14: Fibra de Carbono | F14: Fibra de Vidro | H14: Aramida | J14: Aluminio CHASSI | L14: Aço 1020 | N14: Aço 4340 | P14: Aço 4130 | R14: Aço 1010 | T14: Titânio | V14: Alumínio | X14: Aço inox
A15: Criterio | B15: Peso | C15: Nota | D15: Total | E15: Rating | F15: Weighted Rating x Rating | G15: Rating | H15: Weighted Rating x Rating | I15: Rating | J15: Weighted Rating x Rating | K15: Rating | L15: Weighted Rating x Rating | M15: Rating | N15: Weighted Rating x Rating | O15: Rating | P15: Weighted Rating x Rating | Q15: Rating | R15: Weighted Rating x Rating | S15: Rating | T15: Weighted Rating x Rating | U15: Nota | V15: Total | W15: Rating | X15: Weighted Rating x Rating
A16: Modulo de elasticidade | B16: 11 | C16: =1+((('Planilha de Dados'!J3-MIN('Planilha de Dados'!$J$3:$AB$3))/(MAX('Planilha de Dados'!$J$3:$AB$3)-MIN('Planilha de Dados'!$G$3:$AW$3)))*4) -> 5 | D16: =$B16*C16 -> 55 | E16: =1+((('Planilha de Dados'!L3-MIN('Planilha de Dados'!$J$3:$AB$3))/(MAX('Planilha de Dados'!$J$3:$AB$3)-MIN('Planilha de Dados'!$G$3:$AW$3)))*4) -> 1 | F16: =$B16*E16 -> 11 | G16: =1+((('Planilha de Dados'!N3-MIN('Planilha de Dados'!$J$3:$AB$3))/(MAX('Planilha de Dados'!$J$3:$AB$3)-MIN('Planilha de Dados'!$G$3:$AW$3)))*4) -> 2.1058824 | H16: =$B16*G16 -> 23.164706 | I16: =1+((('Planilha de Dados'!P3-MIN('Planilha de Dados'!$J$3:$AB$3))/(MAX('Planilha de Dados'!$J$3:$AB$3)-MIN('Planilha de Dados'!$G$3:$AW$3)))*4) -> 2.0352941 | J16: =$B16*I16 -> 22.388235 | K16: =1+((('Planilha de Dados'!R3-MIN('Planilha de Dados'!$J$3:$AB$3))/(MAX('Planilha de Dados'!$J$3:$AB$3)-MIN('Planilha de Dados'!$G$3:$AW$3)))*4) -> 4.0588235 | L16: =$B16*K16 -> 44.647059 | M16: =1+((('Planilha de Dados'!T3-MIN('Planilha de Dados'!$J$3:$AB$3))/(MAX('Planilha de Dados'!$J$3:$AB$3)-MIN('Planilha de Dados'!$G$3:$AW$3)))*4) -> 4.1764706 | N16: =$B16*M16 -> 45.941176 | O16: =1+((('Planilha de Dados'!V3-MIN('Planilha de Dados'!$J$3:$AB$3))/(MAX('Planilha de Dados'!$J$3:$AB$3)-MIN('Planilha de Dados'!$G$3:$AW$3)))*4) -> 4.1764706 | P16: =$B16*O16 -> 45.941176 | Q16: =1+((('Planilha de Dados'!X3-MIN('Planilha de Dados'!$J$3:$AB$3))/(MAX('Planilha de Dados'!$J$3:$AB$3)-MIN('Planilha de Dados'!$G$3:$AW$3)))*4) -> 4.0588235 | R16: =$B16*Q16 -> 44.647059 | S16: =1+((('Planilha de Dados'!Z3-MIN('Planilha de Dados'!$J$3:$AB$3))/(MAX('Planilha de Dados'!$J$3:$AB$3)-MIN('Planilha de Dados'!$G$3:$AW$3)))*4) -> 1.8235294 | T16: =$B16*S16 -> 20.058824 | U16: =1+((('Planilha de Dados'!AB3-MIN('Planilha de Dados'!$J$3:$AB$3))/(MAX('Planilha de Dados'!$J$3:$AB$3)-MIN('Planilha de Dados'!$G$3:$AW$3)))*4) -> 2.0352941 | V16: =$B16*U16 -> 22.388235 | W16: =1+((('Planilha de Dados'!AD3-MIN('Planilha de Dados'!$J$3:$AB$3))/(MAX('Planilha de Dados'!$J$3:$AB$3)-MIN('Planilha de Dados'!$G$3:$AW$3)))*4) -> 3.8941176 | X16: =$B16*W16 -> 42.835294
A17: Durabilidade | B17: 15 | C17: =1+((('Planilha de Dados'!J4-MIN('Planilha de Dados'!$G$4:$AW$4))/(MAX('Planilha de Dados'!$G$4:$AW$4)-MIN('Planilha de Dados'!$G$4:$AW$4)))*4) -> 5 | D17: =$B17*C17 -> 75 | E17: =1+((('Planilha de Dados'!L4-MIN('Planilha de Dados'!$G$4:$AW$4))/(MAX('Planilha de Dados'!$G$4:$AW$4)-MIN('Planilha de Dados'!$G$4:$AW$4)))*4) -> 1.5521127 | F17: =$B17*E17 -> 23.28169 | G17: =1+((('Planilha de Dados'!N4-MIN('Planilha de Dados'!$G$4:$AW$4))/(MAX('Planilha de Dados'!$G$4:$AW$4)-MIN('Planilha de Dados'!$G$4:$AW$4)))*4) -> 4.4535211 | H17: =$B17*G17 -> 66.802817 | I17: =1+((('Planilha de Dados'!P4-MIN('Planilha de Dados'!$G$4:$AW$4))/(MAX('Planilha de Dados'!$G$4:$AW$4)-MIN('Planilha de Dados'!$G$4:$AW$4)))*4) -> 1 | J17: =$B17*I17 -> 15 | K17: =1+((('Planilha de Dados'!R4-MIN('Planilha de Dados'!$G$4:$AW$4))/(MAX('Planilha de Dados'!$G$4:$AW$4)-MIN('Planilha de Dados'!$G$4:$AW$4)))*4) -> 1.5915493 | L17: =$B17*K17 -> 23.873239 | M17: =1+((('Planilha de Dados'!T4-MIN('Planilha de Dados'!$G$4:$AW$4))/(MAX('Planilha de Dados'!$G$4:$AW$4)-MIN('Planilha de Dados'!$G$4:$AW$4)))*4) -> 3.4225352 | N17: =$B17*M17 -> 51.338028 | O17: =1+((('Planilha de Dados'!V4-MIN('Planilha de Dados'!$G$4:$AW$4))/(MAX('Planilha de Dados'!$G$4:$AW$4)-MIN('Planilha de Dados'!$G$4:$AW$4)))*4) -> 2.7464789 | P17: =$B17*O17 -> 41.197183 | Q17: =1+((('Planilha de Dados'!X4-MIN('Planilha de Dados'!$G$4:$AW$4))/(MAX('Planilha de Dados'!$G$4:$AW$4)-MIN('Planilha de Dados'!$G$4:$AW$4)))*4) -> 1.3943662 | R17: =$B17*Q17 -> 20.915493 | S17: =1+((('Planilha de Dados'!Z4-MIN('Planilha de Dados'!$G$4:$AW$4))/(MAX('Planilha de Dados'!$G$4:$AW$4)-MIN('Planilha de Dados'!$G$4:$AW$4)))*4) -> 2.915493 | T17: =$B17*S17 -> 43.732394 | U17: =1+((('Planilha de Dados'!AB4-MIN('Planilha de Dados'!$G$4:$AW$4))/(MAX('Planilha de Dados'!$G$4:$AW$4)-MIN('Planilha de Dados'!$G$4:$AW$4)))*4) -> 1 | V17: =$B17*U17 -> 15 | W17: =1+((('Planilha de Dados'!AD4-MIN('Planilha de Dados'!$G$4:$AW$4))/(MAX('Planilha de Dados'!$G$4:$AW$4)-MIN('Planilha de Dados'!$G$4:$AW$4)))*4) -> 1.3943662 | X17: =$B17*W17 -> 20.915493
A18: Confiabilidade | B18: 20 | C18: =1+((('Planilha de Dados'!J5-MIN('Planilha de Dados'!$J$5:$AB$5))/(MAX('Planilha de Dados'!$J$5:$AB$5)-MIN('Planilha de Dados'!$J$5:$AB$5)))*4) -> 5 | D18: =$B18*C18 -> 100 | E18: =1+((('Planilha de Dados'!L5-MIN('Planilha de Dados'!$J$5:$AB$5))/(MAX('Planilha de Dados'!$J$5:$AB$5)-MIN('Planilha de Dados'!$J$5:$AB$5)))*4) -> 1.6 | F18: =$B18*E18 -> 32 | G18: =1+((('Planilha de Dados'!N5-MIN('Planilha de Dados'!$J$5:$AB$5))/(MAX('Planilha de Dados'!$J$5:$AB$5)-MIN('Planilha de Dados'!$J$5:$AB$5)))*4) -> 4.4311111 | H18: =$B18*G18 -> 88.622222 | I18: =1+((('Planilha de Dados'!P5-MIN('Planilha de Dados'!$J$5:$AB$5))/(MAX('Planilha de Dados'!$J$5:$AB$5)-MIN('Planilha de Dados'!$J$5:$AB$5)))*4) -> 2.1555556 | J18: =$B18*I18 -> 43.111111 | K18: =1+((('Planilha de Dados'!R5-MIN('Planilha de Dados'!$J$5:$AB$5))/(MAX('Planilha de Dados'!$J$5:$AB$5)-MIN('Planilha de Dados'!$J$5:$AB$5)))*4) -> 1.6666667 | L18: =$B18*K18 -> 33.333333 | M18: =1+((('Planilha de Dados'!T5-MIN('Planilha de Dados'!$J$5:$AB$5))/(MAX('Planilha de Dados'!$J$5:$AB$5)-MIN('Planilha de Dados'!$J$5:$AB$5)))*4) -> 2.2 | N18: =$B18*M18 -> 44 | O18: =1+((('Planilha de Dados'!V5-MIN('Planilha de Dados'!$J$5:$AB$5))/(MAX('Planilha de Dados'!$J$5:$AB$5)-MIN('Planilha de Dados'!$J$5:$AB$5)))*4) -> 2.0444444 | P18: =$B18*O18 -> 40.888889 | Q18: =1+((('Planilha de Dados'!X5-MIN('Planilha de Dados'!$J$5:$AB$5))/(MAX('Planilha de Dados'!$J$5:$AB$5)-MIN('Planilha de Dados'!$J$5:$AB$5)))*4) -> 1 | R18: =$B18*Q18 -> 20 | S18: =1+((('Planilha de Dados'!Z5-MIN('Planilha de Dados'!$J$5:$AB$5))/(MAX('Planilha de Dados'!$J$5:$AB$5)-MIN('Planilha de Dados'!$J$5:$AB$5)))*4) -> 4.2888889 | T18: =$B18*S18 -> 85.777778 | U18: =1+((('Planilha de Dados'!AB5-MIN('Planilha de Dados'!$J$5:$AB$5))/(MAX('Planilha de Dados'!$J$5:$AB$5)-MIN('Planilha de Dados'!$J$5:$AB$5)))*4) -> 2.1555556 | V18: =$B18*U18 -> 43.111111 | W18: =1+((('Planilha de Dados'!AD5-MIN('Planilha de Dados'!$J$5:$AB$5))/(MAX('Planilha de Dados'!$J$5:$AB$5)-MIN('Planilha de Dados'!$J$5:$AB$5)))*4) -> 1.0666667 | X18: =$B18*W18 -> 21.333333
A19: Manufatura | B19: 15 | C19: =1+((('Planilha de Dados'!J6-MIN('Planilha de Dados'!$J$6:$AB$6))/(MAX('Planilha de Dados'!$J$6:$AB$6)-MIN('Planilha de Dados'!$J$6:$AB$6)))*4) -> 5 | D19: =$B19*C19 -> 75 | E19: =1+((('Planilha de Dados'!L6-MIN('Planilha de Dados'!$J$6:$AB$6))/(MAX('Planilha de Dados'!$J$6:$AB$6)-MIN('Planilha de Dados'!$J$6:$AB$6)))*4) -> 4.9127022 | F19: =$B19*E19 -> 73.690533 | G19: =1+((('Planilha de Dados'!N6-MIN('Planilha de Dados'!$J$6:$AB$6))/(MAX('Planilha de Dados'!$J$6:$AB$6)-MIN('Planilha de Dados'!$J$6:$AB$6)))*4) -> 4.1396069 | H19: =$B19*G19 -> 62.094103 | I19: =1+((('Planilha de Dados'!P6-MIN('Planilha de Dados'!$J$6:$AB$6))/(MAX('Planilha de Dados'!$J$6:$AB$6)-MIN('Planilha de Dados'!$J$6:$AB$6)))*4) -> 3.389391 | J19: =$B19*I19 -> 50.840865 | K19: =1+((('Planilha de Dados'!R6-MIN('Planilha de Dados'!$J$6:$AB$6))/(MAX('Planilha de Dados'!$J$6:$AB$6)-MIN('Planilha de Dados'!$J$6:$AB$6)))*4) -> 4.8745684 | L19: =$B19*K19 -> 73.118527 | M19: =1+((('Planilha de Dados'!T6-MIN('Planilha de Dados'!$J$6:$AB$6))/(MAX('Planilha de Dados'!$J$6:$AB$6)-MIN('Planilha de Dados'!$J$6:$AB$6)))*4) -> 4.8745684 | N19: =$B19*M19 -> 73.118527 | O19: =1+((('Planilha de Dados'!V6-MIN('Planilha de Dados'!$J$6:$AB$6))/(MAX('Planilha de Dados'!$J$6:$AB$6)-MIN('Planilha de Dados'!$J$6:$AB$6)))*4) -> 4.8745684 | P19: =$B19*O19 -> 73.118527 | Q19: =1+((('Planilha de Dados'!X6-MIN('Planilha de Dados'!$J$6:$AB$6))/(MAX('Planilha de Dados'!$J$6:$AB$6)-MIN('Planilha de Dados'!$J$6:$AB$6)))*4) -> 4.8745684 | R19: =$B19*Q19 -> 73.118527 | S19: =1+((('Planilha de Dados'!Z6-MIN('Planilha de Dados'!$J$6:$AB$6))/(MAX('Planilha de Dados'!$J$6:$AB$6)-MIN('Planilha de Dados'!$J$6:$AB$6)))*4) -> 1 | T19: =$B19*S19 -> 15 | U19: =1+((('Planilha de Dados'!AB6-MIN('Planilha de Dados'!$J$6:$AB$6))/(MAX('Planilha de Dados'!$J$6:$AB$6)-MIN('Planilha de Dados'!$J$6:$AB$6)))*4) -> 2.1833716 | V19: =$B19*U19 -> 32.750573 | W19: =1+((('Planilha de Dados'!AD6-MIN('Planilha de Dados'!$J$6:$AB$6))/(MAX('Planilha de Dados'!$J$6:$AB$6)-MIN('Planilha de Dados'!$J$6:$AB$6)))*4) -> 3.0746772 | X19: =$B19*W19 -> 46.120157
A20: Conhecimento da equipe | B20: 17 | C20: =1+((('Planilha de Dados'!J7-MIN('Planilha de Dados'!$J$7:$AB$7))/(MAX('Planilha de Dados'!$J$7:$AB$7)-MIN('Planilha de Dados'!$J$7:$AB$7)))*4) -> 5 | D20: =$B20*C20 -> 85 | E20: =1+((('Planilha de Dados'!L7-MIN('Planilha de Dados'!$J$7:$AB$7))/(MAX('Planilha de Dados'!$J$7:$AB$7)-MIN('Planilha de Dados'!$J$7:$AB$7)))*4) -> 5 | F20: =$B20*E20 -> 85 | G20: =1+((('Planilha de Dados'!N7-MIN('Planilha de Dados'!$J$7:$AB$7))/(MAX('Planilha de Dados'!$J$7:$AB$7)-MIN('Planilha de Dados'!$J$7:$AB$7)))*4) -> 3 | H20: =$B20*G20 -> 51 | I20: =1+((('Planilha de Dados'!P7-MIN('Planilha de Dados'!$J$7:$AB$7))/(MAX('Planilha de Dados'!$J$7:$AB$7)-MIN('Planilha de Dados'!$J$7:$AB$7)))*4) -> 5 | J20: =$B20*I20 -> 85 | K20: =1+((('Planilha de Dados'!R7-MIN('Planilha de Dados'!$J$7:$AB$7))/(MAX('Planilha de Dados'!$J$7:$AB$7)-MIN('Planilha de Dados'!$J$7:$AB$7)))*4) -> 5 | L20: =$B20*K20 -> 85 | M20: =1+((('Planilha de Dados'!T7-MIN('Planilha de Dados'!$J$7:$AB$7))/(MAX('Planilha de Dados'!$J$7:$AB$7)-MIN('Planilha de Dados'!$J$7:$AB$7)))*4) -> 3 | N20: =$B20*M20 -> 51 | O20: =1+((('Planilha de Dados'!V7-MIN('Planilha de Dados'!$J$7:$AB$7))/(MAX('Planilha de Dados'!$J$7:$AB$7)-MIN('Planilha de Dados'!$J$7:$AB$7)))*4) -> 2 | P20: =$B20*O20 -> 34 | Q20: =1+((('Planilha de Dados'!X7-MIN('Planilha de Dados'!$J$7:$AB$7))/(MAX('Planilha de Dados'!$J$7:$AB$7)-MIN('Planilha de Dados'!$J$7:$AB$7)))*4) -> 5 | R20: =$B20*Q20 -> 85 | S20: =1+((('Planilha de Dados'!Z7-MIN('Planilha de Dados'!$J$7:$AB$7))/(MAX('Planilha de Dados'!$J$7:$AB$7)-MIN('Planilha de Dados'!$J$7:$AB$7)))*4) -> 1 | T20: =$B20*S20 -> 17 | U20: =1+((('Planilha de Dados'!AB7-MIN('Planilha de Dados'!$J$7:$AB$7))/(MAX('Planilha de Dados'!$J$7:$AB$7)-MIN('Planilha de Dados'!$J$7:$AB$7)))*4) -> 5 | V20: =$B20*U20 -> 85 | W20: =1+((('Planilha de Dados'!AD7-MIN('Planilha de Dados'!$J$7:$AB$7))/(MAX('Planilha de Dados'!$J$7:$AB$7)-MIN('Planilha de Dados'!$J$7:$AB$7)))*4) -> 2 | X20: =$B20*W20 -> 34
A21: Peso | B21: 22 | C21: =1+(((MAX('Planilha de Dados'!$G$8:$AW$8)-'Planilha de Dados'!J8)/(MAX('Planilha de Dados'!$G$8:$AW$8)-MIN('Planilha de Dados'!$G$8:$AW8)))*4) -> 4.7884914 | D21: =$B21*C21 -> 105.34681 | E21: =1+(((MAX('Planilha de Dados'!$G$8:$AW$8)-'Planilha de Dados'!L8)/(MAX('Planilha de Dados'!$G$8:$AW$8)-MIN('Planilha de Dados'!$G$8:$AW8)))*4) -> 4.3903577 | F21: =$B21*E21 -> 96.587869 | G21: =1+(((MAX('Planilha de Dados'!$G$8:$AW$8)-'Planilha de Dados'!N8)/(MAX('Planilha de Dados'!$G$8:$AW$8)-MIN('Planilha de Dados'!$G$8:$AW8)))*4) -> 5 | H21: =$B21*G21 -> 110 | I21: =1+(((MAX('Planilha de Dados'!$G$8:$AW$8)-'Planilha de Dados'!P8)/(MAX('Planilha de Dados'!$G$8:$AW$8)-MIN('Planilha de Dados'!$G$8:$AW8)))*4) -> 4.2037325 | J21: =$B21*I21 -> 92.482115 | K21: =1+(((MAX('Planilha de Dados'!$G$8:$AW$8)-'Planilha de Dados'!R8)/(MAX('Planilha de Dados'!$G$8:$AW$8)-MIN('Planilha de Dados'!$G$8:$AW8)))*4) -> 1 | L21: =$B21*K21 -> 22 | M21: =1+(((MAX('Planilha de Dados'!$G$8:$AW$8)-'Planilha de Dados'!T8)/(MAX('Planilha de Dados'!$G$8:$AW$8)-MIN('Planilha de Dados'!$G$8:$AW8)))*4) -> 1 | N21: =$B21*M21 -> 22 | O21: =1+(((MAX('Planilha de Dados'!$G$8:$AW$8)-'Planilha de Dados'!V8)/(MAX('Planilha de Dados'!$G$8:$AW$8)-MIN('Planilha de Dados'!$G$8:$AW8)))*4) -> 1 | P21: =$B21*O21 -> 22 | Q21: =1+(((MAX('Planilha de Dados'!$G$8:$AW$8)-'Planilha de Dados'!X8)/(MAX('Planilha de Dados'!$G$8:$AW$8)-MIN('Planilha de Dados'!$G$8:$AW8)))*4) -> 1 | R21: =$B21*Q21 -> 22 | S21: =1+(((MAX('Planilha de Dados'!$G$8:$AW$8)-'Planilha de Dados'!Z8)/(MAX('Planilha de Dados'!$G$8:$AW$8)-MIN('Planilha de Dados'!$G$8:$AW8)))*4) -> 3.0839813 | T21: =$B21*S21 -> 67.847589 | U21: =1+(((MAX('Planilha de Dados'!$G$8:$AW$8)-'Planilha de Dados'!AB8)/(MAX('Planilha de Dados'!$G$8:$AW$8)-MIN('Planilha de Dados'!$G$8:$AW8)))*4) -> 4.2037325 | V21: =$B21*U21 -> 92.482115 | W21: =1+(((MAX('Planilha de Dados'!$G$8:$AW$8)-'Planilha de Dados'!AD8)/(MAX('Planilha de Dados'!$G$8:$AW$8)-MIN('Planilha de Dados'!$G$8:$AW8)))*4) -> 1 | X21: =$B21*W21 -> 22
A22: Somatório total | B22: =SUM(B16:B21) -> 100 | C22: =SUM(C16:C21) -> 29.788491 | D22: =SUM(D16:D21) -> 495.34681 | E22: =SUM(E16:E21) -> 18.455173 | F22: =SUM(F16:F21) -> 321.56009 | G22: =SUM(G16:G21) -> 23.130121 | H22: =SUM(H16:H21) -> 401.68385 | I22: =SUM(I16:I21) -> 17.783973 | ... X22: =SUM(X16:X21) -> 187.20428
A23: Rating Scale | B23: 1-Doesn't Meet Criteria | C23: 2-Somewhat Meets Criteria | E23: 3-Meets Criteria | G23: 4-Excceeds Criteria | I23: 5-Significantly Exceeds Criteria

Sheet Cost metais
A1: University | B1: Universidade Federal de Minas Gerais | J1: Car # | K1: 2 | M1: Part Cost | N1: =N57+I79+I87 -> 398.53056
A2: System | B2: Frame & body | M2: Qty | N2: 1
A3: Assembly | B3: Tubular Frame | D3: Material: | E3: Aço | G3: =1.93/1.2 -> 1.6083333 | J3: FileLink1 | K3: BOM
A4: Part | B4: Frame Tubes | J4: FileLink2 | K4: Cost Summary | M4: Extended Cost | N4: =N1*N2 -> 398.53056
A5: P/N Base | B5: FR00001 | G5: =1.96/1.2 -> 1.6333333 | J5: FileLink3 | K5: A_Tubular Frame
A6: Suffix | B6: AA
A7: Details | B7: Part responsible for structural support of the car
A9: ItemOrder | B9: Material | C9: Use | D9: = | E9: Size1 | F9: Unit1 | G9: Size2 | H9: Unit2 | I9: Area Name | J9: Area | K9: Length | L9: Density | M9: Quantity | N9: Sub Total
A10: M1 | B10: Tubing, Steel | C10: Front Bulkhead (Pink in Rendering) | D10: =IF($E$3="Aluminio",4.2,IF($E$3="Titanio",22,2.25)) -> 2.25 | E10: =J10*K10*L10 -> 0.27526559 | F10: kg | I10: Square, 25x25x1,2 mm | J10: =IF($E$3="Aluminio",0.00011239*1.46,IF($E$3="Titanio",0.00011239*0.4,IF($E$3="Inox",0.00011239*1.61,0.00011239))) -> 0.00011239 | K10: 0.312 | L10: =IF(OR($E$3="Aço",$E$3="Inox"),7850,IF($E$3="Titanio",4500,2712)) -> 7850 | M10: 5 | N10: =D10*E10*M10 -> 3.0967379
A11: M2 | B11: Tubing, Steel | C11: Upper Front Bulkhead Supports (White in Rendering) | D11: =IF($E$3="Aluminio",4.2,IF($E$3="Titanio",22,2.25)) -> 2.25 | E11: =J11*K11*L11 -> 0.29132803 | F11: kg | I11: Round, 25,4 x 1,2 mm | J11: =IF($E$3="Aluminio",0.00009135*3.04,IF($E$3="Titanio",0.00009135/(1.2/0.48),IF($E$3="Inox",0.00009135*1.63,0.00009135))) -> 9.135e-05 | K11: 0.40626 | L11: =IF(OR($E$3="Aço",$E$3="Inox"),7850,IF($E$3="Titanio",4500,2712)) -> 7850 | M11: 2 | N11: =D11*E11*M11 -> 1.3109761
A12: M3 | B12: Tubing, Steel | C12: Lower Front Bulkhead Supports (Green in Rendering) | D12: =IF($E$3="Aluminio",4.2,IF($E$3="Titanio",22,2.25)) -> 2.25 | E12: =J12*K12*L12 -> 0.43073896 | F12: kg | I12: Round, 25,4 x 1,2 mm | J12: =IF($E$3="Aluminio",0.00009135*3.04,IF($E$3="Titanio",0.00009135/(1.2/0.48),IF($E$3="Inox",0.00009135*1.63,0.00009135))) -> 9.135e-05 | K12: 0.60067 | L12: =IF(OR($E$3="Aço",$E$3="Inox"),7850,IF($E$3="Titanio",4500,2712)) -> 7850 | M12: 2 | N12: =D12*E12*M12 -> 1.9383253
A13: M4 | B13: Tubing, Steel | C13: Diagonal Front Bulkhead Supports 1 (Red in Rendering) | D13: =IF($E$3="Aluminio",4.2,IF($E$3="Titanio",22,2.25)) -> 2.25 | E13: =J13*K13*L13 -> 0.27672075 | F13: kg | I13: Round, 25,4 x 1,2 mm | J13: =IF($E$3="Aluminio",0.00009135*3.04,IF($E$3="Titanio",0.00009135/(1.2/0.48),IF($E$3="Inox",0.00009135*1.63,0.00009135))) -> 9.135e-05 | K13: 0.38589 | L13: =IF(OR($E$3="Aço",$E$3="Inox"),7850,IF($E$3="Titanio",4500,2712)) -> 7850 | M13: 2 | N13: =D13*E13*M13 -> 1.2452434
A14: M5 | B14: Tubing, Steel | C14: Diagonal Front Bulkhead Supports 2 (Orange in Rendering) | D14: =IF($E$3="Aluminio",4.2,IF($E$3="Titanio",22,2.25)) -> 2.25 | E14: =J14*K14*L14 -> 0.18111014 | F14: kg | I14: Round, 25,4 x 1,2 mm | J14: =IF($E$3="Aluminio",0.00009135*3.04,IF($E$3="Titanio",0.00009135/(1.2/0.48),IF($E$3="Inox",0.00009135*1.63,0.00009135))) -> 9.135e-05 | K14: 0.25256 | L14: =IF(OR($E$3="Aço",$E$3="Inox"),7850,IF($E$3="Titanio",4500,2712)) -> 7850 | M14: 2 | N14: =D14*E14*M14 -> 0.81499565
A15: M6 | B15: Tubing, Steel | C15: Diagonal Front Bulkhead Supports 3 (Pink in rending) | D15: =IF($E$3="Aluminio",4.2,IF($E$3="Titanio",22,2.25)) -> 2.25 | E15: =J15*K15*L15 -> 0.17585382 | F15: kg | I15: Round, 25,4 x 1,2 mm | J15: =IF($E$3="Aluminio",0.00009135*3.04,IF($E$3="Titanio",0.00009135/(1.2/0.48),IF($E$3="Inox",0.00009135*1.63,0.00009135))) -> 9.135e-05 | K15: 0.24523 | L15: =IF(OR($E$3="Aço",$E$3="Inox"),7850,IF($E$3="Titanio",4500,2712)) -> 7850 | M15: 2 | N15: =D15*E15*M15 -> 0.79134219
A16: M7 | B16: Tubing, Steel | C16: Diagonal Front Bulkhead Supports 4 (Cian in rending) | D16: =IF($E$3="Aluminio",4.2,IF($E$3="Titanio",22,2.25)) -> 2.25 | E16: =J16*K16*L16 -> 0.057505395 | F16: kg | I16: Round, 15,87 x 0,75 mm | J16: =IF($E$3="Aluminio",0.00003563*3.04,IF($E$3="Titanio",0.00003563/(1.2/0.48),IF($E$3="Inox",0.00003563*1.63,0.00003563))) -> 3.563e-05 | K16: 0.2056 | L16: =IF(OR($E$3="Aço",$E$3="Inox"),7850,IF($E$3="Titanio",4500,2712)) -> 7850 | M16: 2 | N16: =D16*E16*M16 -> 0.25877428
A17: M8 | B17: Tubing, Steel | C17: Front Hoop Bracing (Cian in Rendering) | D17: =IF($E$3="Aluminio",4.2,IF($E$3="Titanio",22,2.25)) -> 2.25 | E17: =J17*K17*L17 -> 0.54611987 | F17: kg | I17: Square, 25x25x1,2 mm | J17: =IF($E$3="Aluminio",0.00011239*1.46,IF($E$3="Titanio",0.00011239*0.4,IF($E$3="Inox",0.00011239*1.61,0.00011239))) -> 0.00011239 | K17: 0.619 | L17: =IF(OR($E$3="Aço",$E$3="Inox"),7850,IF($E$3="Titanio",4500,2712)) -> 7850 | M17: 2 | N17: =D17*E17*M17 -> 2.4575394
A18: M9 | B18: Tubing, Steel | C18: Front Non-Structural Tubing 1 (Yellow in Rendering) | D18: =IF($E$3="Aluminio",4.2,IF($E$3="Titanio",22,2.25)) -> 2.25 | E18: =J18*K18*L18 -> 0.11668696 | F18: kg | I18: Round, 25,4 x 0,9 mm | J18: =IF($E$3="Aluminio",0.00006926*3.04,IF($E$3="Titanio",0.00006926/(1.2/0.48),IF($E$3="Inox",0.00006926*1.63,0.00006926))) -> 6.926e-05 | K18: 0.21462 | L18: =IF(OR($E$3="Aço",$E$3="Inox"),7850,IF($E$3="Titanio",4500,2712)) -> 7850 | M18: 2 | N18: =D18*E18*M18 -> 0.52509133
A19: M10 | B19: Tubing, Steel | C19: Upper Front Non-Structural Tubing 2 (Red in Rendering) | D19: =IF($E$3="Aluminio",4.2,IF($E$3="Titanio",22,2.25)) -> 2.25 | E19: =J19*K19*L19 -> 0.1201829 | F19: kg | I19: Round, 25,4 x 0,9 mm | J19: =IF($E$3="Aluminio",0.00006926*3.04,IF($E$3="Titanio",0.00006926/(1.2/0.48),IF($E$3="Inox",0.00006926*1.63,0.00006926))) -> 6.926e-05 | K19: 0.22105 | L19: =IF(OR($E$3="Aço",$E$3="Inox"),7850,IF($E$3="Titanio",4500,2712)) -> 7850 | M19: 2 | N19: =D19*E19*M19 -> 0.54082303
A20: M11 | B20: Tubing, Steel | C20: Lower Front Non-Structural Tubing 3 (White in Rendering) | D20: =IF($E$3="Aluminio",4.2,IF($E$3="Titanio",22,2.25)) -> 2.25 | E20: =J20*K20*L20 -> 0.057930276 | F20: kg | I20: Round, 25,4 x 0,9 mm | J20: =IF($E$3="Aluminio",0.00006926*3.04,IF($E$3="Titanio",0.00006926/(1.2/0.48),IF($E$3="Inox",0.00006926*1.63,0.00006926))) -> 6.926e-05 | K20: 0.10655 | L20: =IF(OR($E$3="Aço",$E$3="Inox"),7850,IF($E$3="Titanio",4500,2712)) -> 7850 | M20: 2 | N20: =D20*E20*M20 -> 0.26068624
A21: M12 | B21: Tubing, Steel | C21: Front Hoop (Blue in Rendering) | D21: =IF($E$3="Aluminio",4.2,IF($E$3="Titanio",22,2.25)) -> 2.25 | E21: =J21*K21*L21 -> 1.976661 | F21: kg | I21: Round, 25,4 x 2,4mm | J21: =IF($E$3="Aluminio",0.00017361*3.04,IF($E$3="Titanio",0.00017361/(1.2/0.48),IF($E$3="Inox",0.00017361*1.63,0.00017361))) -> 0.00017361 | K21: 1.4504 | L21: =IF(OR($E$3="Aço",$E$3="Inox"),7850,IF($E$3="Titanio",4500,2712)) -> 7850 | M21: 1 | N21: =D21*E21*M21 -> 4.4474872
A22: M13 | B22: Tubing, Steel | C22: Floor Closeout Tubing 1 (Yellow in Rendering) | D22: =IF($E$3="Aluminio",4.2,IF($E$3="Titanio",22,2.25)) -> 2.25 | E22: =J22*K22*L22 -> 0.087181087 | F22: kg | I22: Round, 15,87 x 0,75 mm | J22: =IF($E$3="Aluminio",0.00003563*3.04,IF($E$3="Titanio",0.00003563/(1.2/0.48),IF($E$3="Inox",0.00003563*1.63,0.00003563))) -> 3.563e-05 | K22: 0.3117 | L22: =IF(OR($E$3="Aço",$E$3="Inox"),7850,IF($E$3="Titanio",4500,2712)) -> 7850 | M22: 1 | N22: =D22*E22*M22 -> 0.19615745
A23: M14 | B23: Tubing, Steel | C23: Floor Closeout Tubing 2 (White in Rendering) | D23: =IF($E$3="Aluminio",4.2,IF($E$3="Titanio",22,2.25)) -> 2.25 | E23: =J23*K23*L23 -> 0.086672042 | F23: kg | I23: Round, 15,87 x 0,75 mm | J23: =IF($E$3="Aluminio",0.00003563*3.04,IF($E$3="Titanio",0.00003563/(1.2/0.48),IF($E$3="Inox",0.00003563*1.63,0.00003563))) -> 3.563e-05 | K23: 0.30988 | L23: =IF(OR($E$3="Aço",$E$3="Inox"),7850,IF($E$3="Titanio",4500,2712)) -> 7850 | M23: 1 | N23: =D23*E23*M23 -> 0.19501209
A24: M15 | B24: Tubing, Steel | C24: Diagonal Floor Closeout Tubing (Orange in Rendering) | D24: =IF($E$3="Aluminio",4.2,IF($E$3="Titanio",22,2.25)) -> 2.25 | E24: =J24*K24*L24 -> 0.057278841 | F24: kg | I24: Round, 15,87 x 0,75 mm | J24: =IF($E$3="Aluminio",0.00003563*3.04,IF($E$3="Titanio",0.00003563/(1.2/0.48),IF($E$3="Inox",0.00003563*1.63,0.00003563))) -> 3.563e-05 | K24: 0.20479 | L24: =IF(OR($E$3="Aço",$E$3="Inox"),7850,IF($E$3="Titanio",4500,2712)) -> 7850 | M24: 2 | N24: =D24*E24*M24 -> 0.25775479
A25: M16 | B25: Tubing, Steel | C25: Cockpit Closeout (Pink in Rendering) | D25: =IF($E$3="Aluminio",4.2,IF($E$3="Titanio",22,2.25)) -> 2.25 | E25: =J25*K25*L25 -> 0.10106517 | F25: kg | I25: Round, 15,87 x 0,75 mm | J25: =IF($E$3="Aluminio",0.00003563*3.04,IF($E$3="Titanio",0.00003563/(1.2/0.48),IF($E$3="Inox",0.00003563*1.63,0.00003563))) -> 3.563e-05 | K25: 0.36134 | L25: =IF(OR($E$3="Aço",$E$3="Inox"),7850,IF($E$3="Titanio",4500,2712)) -> 7850 | M25: 2 | N25: =D25*E25*M25 -> 0.45479327
A26: M17 | B26: Tubing, Steel | C26: Upper Side Impact Structure (Cian in Rendering) | D26: =IF($E$3="Aluminio",4.2,IF($E$3="Titanio",22,2.25)) -> 2.25 | E26: =J26*K26*L26 -> 0.71629929 | F26: kg | I26: Square, 25x25x1,2 mm | J26: =IF($E$3="Aluminio",0.00011239*1.46,IF($E$3="Titanio",0.00011239*0.4,IF($E$3="Inox",0.00011239*1.61,0.00011239))) -> 0.00011239 | K26: 0.81189 | L26: =IF(OR($E$3="Aço",$E$3="Inox"),7850,IF($E$3="Titanio",4500,2712)) -> 7850 | M26: 2 | N26: =D26*E26*M26 -> 3.2233468
A27: M18 | B27: Tubing, Steel | C27: Diagonal Side Impact Structure 1 (Pink in Rendering) | D27: =IF($E$3="Aluminio",4.2,IF($E$3="Titanio",22,2.25)) -> 2.25 | E27: =J27*K27*L27 -> 0.38557474 | F27: kg | I27: Square, 25x25x1,2 mm | J27: =IF($E$3="Aluminio",0.00011239*1.46,IF($E$3="Titanio",0.00011239*0.4,IF($E$3="Inox",0.00011239*1.61,0.00011239))) -> 0.00011239 | K27: 0.43703 | L27: =IF(OR($E$3="Aço",$E$3="Inox"),7850,IF($E$3="Titanio",4500,2712)) -> 7850 | M27: 2 | N27: =D27*E27*M27 -> 1.7350863
A28: M19 | B28: Tubing, Steel | C28: Diagonal Side Impact Structure 2 (Red in Rendering) | D28: =IF($E$3="Aluminio",4.2,IF($E$3="Titanio",22,2.25)) -> 2.25 | E28: =J28*K28*L28 -> 0.44221593 | F28: kg | I28: Square, 25x25x1,2 mm | J28: =IF($E$3="Aluminio",0.00011239*1.46,IF($E$3="Titanio",0.00011239*0.4,IF($E$3="Inox",0.00011239*1.61,0.00011239))) -> 0.00011239 | K28: 0.50123 | L28: =IF(OR($E$3="Aço",$E$3="Inox"),7850,IF($E$3="Titanio",4500,2712)) -> 7850 | M28: 2 | N28: =D28*E28*M28 -> 1.9899717
A29: M20 | B29: Tubing, Steel | C29: Lower Side Impact Structure 1 (Cian in Rendering) | D29: =IF($E$3="Aluminio",4.2,IF($E$3="Titanio",22,2.25)) -> 2.25 | E29: =J29*K29*L29 -> 0.35049603 | F29: kg | I29: Square, 25x25x1,2 mm | J29: =IF($E$3="Aluminio",0.00011239*1.46,IF($E$3="Titanio",0.00011239*0.4,IF($E$3="Inox",0.00011239*1.61,0.00011239))) -> 0.00011239 | K29: 0.39727 | L29: =IF(OR($E$3="Aço",$E$3="Inox"),7850,IF($E$3="Titanio",4500,2712)) -> 7850 | M29: 2 | N29: =D29*E29*M29 -> 1.5772321
A30: M21 | B30: Tubing, Steel | C30: Lower Side Impact Structure 2 (White in Rendering) | D30: =IF($E$3="Aluminio",4.2,IF($E$3="Titanio",22,2.25)) -> 2.25 | E30: =J30*K30*L30 -> 0.3458818 | F30: kg | I30: Square, 25x25x1,2 mm | J30: =IF($E$3="Aluminio",0.00011239*1.46,IF($E$3="Titanio",0.00011239*0.4,IF($E$3="Inox",0.00011239*1.61,0.00011239))) -> 0.00011239 | K30: 0.39204 | L30: =IF(OR($E$3="Aço",$E$3="Inox"),7850,IF($E$3="Titanio",4500,2712)) -> 7850 | M30: 2 | N30: =D30*E30*M30 -> 1.5564681
A31: M22 | B31: Tubing, Steel | C31: Lower Cockpit Tubing (Green in Rendering) | D31: =IF($E$3="Aluminio",4.2,IF($E$3="Titanio",22,2.25)) -> 2.25 | E31: =J31*K31*L31 -> 0.32358705 | F31: kg | I31: Square, 25x25x1,2 mm | J31: =IF($E$3="Aluminio",0.00011239*1.46,IF($E$3="Titanio",0.00011239*0.4,IF($E$3="Inox",0.00011239*1.61,0.00011239))) -> 0.00011239 | K31: 0.36677 | L31: =IF(OR($E$3="Aço",$E$3="Inox"),7850,IF($E$3="Titanio",4500,2712)) -> 7850 | M31: 1 | N31: =D31*E31*M31 -> 0.72807086
A32: M23 | B32: Tubing, Steel | C32: Main Hoop (Blue in Rendering) | D32: =IF($E$3="Aluminio",4.2,IF($E$3="Titanio",22,2.25)) -> 2.25 | E32: =J32*K32*L32 -> 2.564557 | F32: kg | I32: Round, 25,4 x 2,4mm | J32: =IF($E$3="Aluminio",0.00017361*3.04,IF($E$3="Titanio",0.00017361/(1.2/0.48),IF($E$3="Inox",0.00017361*1.63,0.00017361))) -> 0.00017361 | K32: 1.8817762 | L32: =IF(OR($E$3="Aço",$E$3="Inox"),7850,IF($E$3="Titanio",4500,2712)) -> 7850 | M32: 1 | N32: =D32*E32*M32 -> 5.7702533
A33: M24 | B33: Tubing, Steel | C33: Shoulder Harness Mounting Bar (Pink in Rendering) | D33: =IF($E$3="Aluminio",4.2,IF($E$3="Titanio",22,2.25)) -> 2.25 | E33: =J33*K33*L33 -> 0.68038465 | F33: kg | I33: Round, 25,4 x 2,4mm | J33: =IF($E$3="Aluminio",0.00017361*3.04,IF($E$3="Titanio",0.00017361/(1.2/0.48),IF($E$3="Inox",0.00017361*1.63,0.00017361))) -> 0.00017361 | K33: 0.49924085 | L33: =IF(OR($E$3="Aço",$E$3="Inox"),7850,IF($E$3="Titanio",4500,2712)) -> 7850 | M33: 1 | N33: =D33*E33*M33 -> 1.5308655
A34: M25 | B34: Tubing, Steel | C34: Lower Main Hoop Tubing (Pink in Rendering) | D34: =IF($E$3="Aluminio",4.2,IF($E$3="Titanio",22,2.25)) -> 2.25 | E34: =J34*K34*L34 -> 0.10332617 | F34: kg | I34: Round, 15,87 x 0,75 mm | J34: =IF($E$3="Aluminio",0.00003563*3.04,IF($E$3="Titanio",0.00003563/(1.2/0.48),IF($E$3="Inox",0.00003563*1.63,0.00003563))) -> 3.563e-05 | K34: 0.3694238 | L34: =IF(OR($E$3="Aço",$E$3="Inox"),7850,IF($E$3="Titanio",4500,2712)) -> 7850 | M34: 1 | N34: =D34*E34*M34 -> 0.23248389
A35: M26 | B35: Tubing, Steel | C35: Main Hoop Bracing (Cian in Rendering) | D35: =IF($E$3="Aluminio",4.2,IF($E$3="Titanio",22,2.25)) -> 2.25 | E35: =J35*K35*L35 -> 0.5818401 | F35: kg | I35: Square, 25x25x1,2 mm | J35: =IF($E$3="Aluminio",0.00011239*1.46,IF($E$3="Titanio",0.00011239*0.4,IF($E$3="Inox",0.00011239*1.61,0.00011239))) -> 0.00011239 | K35: 0.65948712 | L35: =IF(OR($E$3="Aço",$E$3="Inox"),7850,IF($E$3="Titanio",4500,2712)) -> 7850 | M35: 2 | N35: =D35*E35*M35 -> 2.6182804
A36: M27 | B36: Tubing, Steel | C36: Upper Main Hoop Bracing Support 1 (Yellow in Rendering) | D36: =IF($E$3="Aluminio",4.2,IF($E$3="Titanio",22,2.25)) -> 2.25 | E36: =J36*K36*L36 -> 0.22442668 | F36: kg | I36: Round, 25,4 x 1,2 mm | J36: =IF($E$3="Aluminio",0.00009135*3.04,IF($E$3="Titanio",0.00009135/(1.2/0.48),IF($E$3="Inox",0.00009135*1.63,0.00009135))) -> 9.135e-05 | K36: 0.31296537 | L36: =IF(OR($E$3="Aço",$E$3="Inox"),7850,IF($E$3="Titanio",4500,2712)) -> 7850 | M36: 2 | N36: =D36*E36*M36 -> 1.0099201
A37: M28 | B37: Tubing, Steel | C37: Upper Main Hoop Bracing Support 2 (Red in Rendering) | D37: =IF($E$3="Aluminio",4.2,IF($E$3="Titanio",22,2.25)) -> 2.25 | E37: =J37*K37*L37 -> 0.1133298 | F37: kg | I37: Round, 25,4 x 1,2 mm | J37: =IF($E$3="Aluminio",0.00009135*3.04,IF($E$3="Titanio",0.00009135/(1.2/0.48),IF($E$3="Inox",0.00009135*1.63,0.00009135))) -> 9.135e-05 | K37: 0.1580396 | L37: =IF(OR($E$3="Aço",$E$3="Inox"),7850,IF($E$3="Titanio",4500,2712)) -> 7850 | M37: 2 | N37: =D37*E37*M37 -> 0.50998411
A38: M29 | B38: Tubing, Steel | C38: Lower Main Hoop Bracing Support 1 (Pink in Rendering) | D38: =IF($E$3="Aluminio",4.2,IF($E$3="Titanio",22,2.25)) -> 2.25 | E38: =J38*K38*L38 -> 0.27099832 | F38: kg | I38: Round, 25,4 x 1,2 mm | J38: =IF($E$3="Aluminio",0.00009135*3.04,IF($E$3="Titanio",0.00009135/(1.2/0.48),IF($E$3="Inox",0.00009135*1.63,0.00009135))) -> 9.135e-05 | K38: 0.37791 | L38: =IF(OR($E$3="Aço",$E$3="Inox"),7850,IF($E$3="Titanio",4500,2712)) -> 7850 | M38: 2 | N38: =D38*E38*M38 -> 1.2194924
A39: M30 | B39: Tubing, Steel | C39: Lower Main Hoop Bracing Support 2 (Red in Rendering) | D39: =IF($E$3="Aluminio",4.2,IF($E$3="Titanio",22,2.25)) -> 2.25 | E39: =J39*K39*L39 -> 0.14377422 | F39: kg | I39: Round, 25,4 x 1,2 mm | J39: =IF($E$3="Aluminio",0.00009135*3.04,IF($E$3="Titanio",0.00009135/(1.2/0.48),IF($E$3="Inox",0.00009135*1.63,0.00009135))) -> 9.135e-05 | K39: 0.20049466 | L39: =IF(OR($E$3="Aço",$E$3="Inox"),7850,IF($E$3="Titanio",4500,2712)) -> 7850 | M39: 2 | N39: =D39*E39*M39 -> 0.64698399
A40: M31 | B40: Tubing, Steel | C40: Lower Main Hoop Bracing Support 3 (Yellow in Rendering) | D40: =IF($E$3="Aluminio",4.2,IF($E$3="Titanio",22,2.25)) -> 2.25 | E40: =J40*K40*L40 -> 0.10223701 | F40: kg | I40: Round, 25,4 x 1,2 mm | J40: =IF($E$3="Aluminio",0.00009135*3.04,IF($E$3="Titanio",0.00009135/(1.2/0.48),IF($E$3="Inox",0.00009135*1.63,0.00009135))) -> 9.135e-05 | K40: 0.14257059 | L40: =IF(OR($E$3="Aço",$E$3="Inox"),7850,IF($E$3="Titanio",4500,2712)) -> 7850 | M40: 2 | N40: =D40*E40*M40 -> 0.46006656
A41: M32 | B41: Tubing, Steel | C41: Lower Main Hoop Bracing Support 4 (Pink in Rendering) | D41: =IF($E$3="Aluminio",4.2,IF($E$3="Titanio",22,2.25)) -> 2.25 | E41: =J41*K41*L41 -> 0.08785723 | F41: kg | I41: Round, 25,4 x 1,2 mm | J41: =IF($E$3="Aluminio",0.00009135*3.04,IF($E$3="Titanio",0.00009135/(1.2/0.48),IF($E$3="Inox",0.00009135*1.63,0.00009135))) -> 9.135e-05 | K41: 0.12251783 | L41: =IF(OR($E$3="Aço",$E$3="Inox"),7850,IF($E$3="Titanio",4500,2712)) -> 7850 | M41: 2 | N41: =D41*E41*M41 -> 0.39535753
...

Sheet Compositos simulaçao
A1: University | B1: Universidade Federal de Minas Gerais | J1: Car # | K1: 2 | M1: Part Cost | N1: =N11+I20+J24+I28 -> 6133.2595
A2: System | B2: Steering System | M2: Qty | N2: 1
A3: Assembly | B3: Steering Wheel | J3: FileLink1 | K3: BOM
A4: Part | B4: Steering Wheel | J4: FileLink2 | K4: Cost Summary | M4: Extended Cost | N4: =N1*N2 -> 6133.2595
A5: P/N Base | B5: ST00002 | J5: FileLink3 | K5: A_Steering Wheel
A6: Suffix | B6: AA
A7: Details | B7: Student made Steering Wheel
A9: ItemOrder | B9: Material | C9: Use | D9: UnitCost | E9: Size1 | F9: Unit1 | G9: Size2 | H9: Unit2 | I9: Area Name | J9: Area | K9: Length | L9: Density | M9: Quantity | N9: Sub Total
A10: M1 | B10: Aramid (Kevlar) Fiber, 1 Ply | C10: =IF(B10="Carbon Fiber, 1 Ply","Carbon Fiber used to laminate Steering Wheel",IF(B10="Glass Fiber, 1 Ply","Glass Fiber used to laminate Steering Wheel",IF(B10="Aramid (Kevlar) Fiber, 1 Ply","Aramid used to laminate Steering Wheel",""))) -> Aramid used to laminate Steering Wheel | D10: =IF(B10="Carbon Fiber, 1 Ply",200,IF(B10="Glass Fiber, 1 Ply",100,IF(B10="Aramid (Kevlar) Fiber, 1 Ply",150,""))) -> 150 | E10: =J10*K10*L10 -> 1.102772 | F10: kg | I10: All sheets | J10: 3.1064 | K10: 0.00025 | L10: =IF(B10="Carbon Fiber, 1 Ply",1580,IF(B10="Glass Fiber, 1 Ply",2200,IF(B10="Aramid (Kevlar) Fiber, 1 Ply",1420,""))) -> 1420 | M10: =IF(B10="Carbon Fiber, 1 Ply",5/0.29,IF(B10="Glass Fiber, 1 Ply",12/0.29,IF(B10="Aramid (Kevlar) Fiber, 1 Ply",10/0.29,""))) -> 34.482759 | N10: =IF(J10="",D10*M10,D10*J10*K10*L10*M10) -> 5703.9931
M11: Sub Total | N11: =SUM(N10:N10) -> 5703.9931 | O11: =N11*$N$2 -> 5703.9931
A13: ItemOrder | B13: Process | C13: Use | D13: UnitCost | E13: Unit | F13: Quantity | G13: Multiplier | H13: Mult. Val. | I13: Sub Total
A14: P1 | B14: Lamination, Manual | C14: Lamination for Steering Wheel (M1) on structural foam (M2) | D14: =IF(B14="Lamination, Manual",35,25) -> 35 | E14: =IF(B14="Lamination, Manual","m^2","kg") -> m^2 | F14: =IF(B14="Lamination, Manual",J10,E10) -> 3.1064 | G14: Repeat 2 - 2 plies | H14: 2 | I14: =IF($H14<>"",$D14*$F14*$H14,$D14*$F14) -> 217.448
A15: P2 | B15: Resin application, Infusion Molding | C15: Resin application for lamination process P1 | D15: =IF(B15="Resin application, Infusion Molding",2.5,5) -> 2.5 | E15: m² | F15: =F14 -> 3.1064 | G15: Repeat 2 - 2 plies | H15: 2 | I15: =IF($H15<>"",$D15*$F15*$H15,$D15*$F15) -> 15.532
A16: P3 | B16: Vacuum Form | C16: Use of vacumm during lamination process P1 | D16: 10 | E16: m² | F16: =F15 -> 3.1064 | I16: =IF($H16<>"",$D16*$F16*$H16,$D16*$F16) -> 31.064
A17: P4 | B17: Cure, Autoclave | C17: Cure for lamination process P1 | D17: =IF(B17="Cure, Room Temperature",10,IF(B17="Cure, Oven",20,IF(B17="Cure, Autoclave",50,""))) -> 50 | E17: m² | F17: =F16 -> 3.1064 | I17: =IF($H17<>"",$D17*$F17*$H17,$D17*$F17) -> 155.32
A18: P5 | B18: Machining Setup, Install and Remove | C18: Setting up lamination product of process P1 for cutting | D18: 1.3 | E18: unit | F18: 1 | I18: =IF($H18<>"",$D18*$F18*$H18,$D18*$F18) -> 1.3
A19: P6 | B19: Waterjet Cut | C19: Cutting Steering Wheel | D19: 0.01 | E19: cm | F19: 704.92 | I19: =IF($H19<>"",$D19*$F19*$H19,$D19*$F19) -> 7.0492
H20: Sub Total | I20: =SUM(I14:I19) -> 427.7132 | J20: =I20*$N$2 -> 427.7132
A22: ItemOrder | B22: Fastener | C22: Use | D22: UnitCost | E22: Size1 | F22: Unit1 | G22: Size2 | H22: Unit2 | I22: Quantity | J22: Sub Total
I24: Sub Total | J24: =SUM(J23) -> 0 | K24: =J24*$N$2 -> 0
A26: ItemOrder | B26: Tooling | C26: Use | D26: UnitCost | E26: Unit | F26: Quantity | G26: PVF | H26: FracIncld | I26: Sub Total
A27: T1 | B27: Lamination - Flat Panel Tool | C27: Lamination on structural foam P1 | D27: 1500 | E27: m² | F27: =J10 -> 3.1064 | G27: 3000 | H27: 1 | I27: =(D27*F27)/(G27*H27) -> 1.5532
H28: Sub Total | I28: =SUM(I27) -> 1.5532 | J28: =I28*$N$2 -> 1.5532

Sheet monocoque aluminio simulaçao
A1: University | B1: Universidade Federal de Minas Gerais | J1: Car # | K1: 2 | M1: Part Cost | N1: =N14+I27+J29+I35 -> 311.45689
A2: System | B2: Steering System | M2: Qty | N2: 1
A3: Assembly | B3: Steering Wheel | J3: FileLink1 | K3: BOM
A4: Part | B4: Steering Wheel | J4: FileLink2 | K4: Cost Summary | M4: Extended Cost | N4: =N1*N2 -> 311.45689
A5: P/N Base | B5: ST00002 | J5: FileLink3 | K5: A_Steering Wheel
A6: Suffix | B6: AA
A7: Details | B7: Student made Steering Wheel
A9: ItemOrder | B9: Material | C9: Use | D9: UnitCost | E9: Size1 | F9: Unit1 | G9: Size2 | H9: Unit2 | I9: Area Name | J9: Area | K9: Length | L9: Density | M9: Quantity | N9: Sub Total
A10: M1 | B10: Aluminum, Premium (by Dimensions) | C10: Metal sheets | D10: 4.2 | E10: =J10*K10*L10 -> 58.971898 | F10: kg | I10: All sheets | J10: 3.1064 | K10: 0.007 | L10: 2712 | M10: 1 | N10: =IF(J10="",D10*M10,D10*J10*K10*L10*M10) -> 247.68197
A11: M2 | B11: Tubing, Steel | C11: Main Hoop (Blue in Rendering) | D11: 2.25 | E11: =J11*K11*L11 -> 2.4763493 | F11: kg | I11: Round, 25,4 x 2,4mm | J11: 0.00017361 | K11: 1.8817762 | L11: 7580 | M11: 1 | N11: =D11*E11*M11 -> 5.571786
A12: M3 | B12: Tubing, Steel | C12: Main Hoop Bracing (Cian in Rendering) | D12: 2.25 | E12: =J12*K12*L12 -> 0.86786118 | F12: kg | I12: Square, 25x25x1,2 mm | J12: 0.00017361 | K12: 0.65948712 | L12: 7580 | M12: 2 | N12: =D12*E12*M12 -> 3.9053753 | O12: =N14*$N$2 -> 263.37263
A13: M4 | B13: Paint, Priming/Protective Finishing | C13: Painting for the Frame Tubes | D13: 2 | E13: =SUM(J10:J12) -> 3.1067472 | F13: m² | M13: 1 | N13: =D13*E13*M13 -> 6.2134944
M14: Sub Total | N14: =SUM(N10:N13) -> 263.37263
A16: ItemOrder | B16: Process | C16: Use | D16: UnitCost | E16: Unit | F16: Quantity | G16: Multiplier | H16: Mult. Val. | I16: Sub Total
A17: P1 | B17: Tube Bends | C17: Bending of Main Hoop | D17: 0.75 | E17: bend | F17: 5 | I17: =IF(H17="", D17*F17,D17*F17*H17) -> 3.75
A18: P2 | B18: Tubing Lasercut Profiling/end preparation | C18: Tubing Lasercut and Fishmouthing in square tubes 25x25x1,2mm:Main Hoop Bracing | D18: 0.04 | E18: cm | F18: 2.5 | G18: Repeat 4 | H18: 4 | I18: =IF(H18="", D18*F18,D18*F18*H18) -> 0.4
A19: P3 | B19: Machining Setup, Install and Remove | C19: Positioning Aluminum plates 5mm for cutting, resulting in 10 pieces | D19: 1.3 | E19: unit | F19: 1 | I19: =IF(H19="", D19*F19,D19*F19*H19) -> 1.3
A20: P4 | B20: Tube End Preperation for Welding | C20: Cleaning all round and square tubes for welding | D20: 0.75 | E20: end | F20: 2 | I20: =IF(H20="", D20*F20,D20*F20*H20) -> 1.5
A21: P5 | B21: Hand Finish - Surface Preperation | C21: Cleaning all 2 mm plates for welding | D21: 0.02 | E21: cm² | F21: 3 | G21: Material - Steel | H21: 3 | I21: =IF(H21="", D21*F21,D21*F21*H21) -> 0.18 | L21: =25^2*2 -> 1250
A22: P6 | B22: Assemble, 1kg, Line-on-line | C22: Fitting all tubes and plates on chassis templates | D22: 0.13 | E22: unit | F22: 3 | I22: =IF(H22="", D22*F22,D22*F22*H22) -> 0.39
A23: P7 | B23: Weld | C23: Welding of all tubes and plates | D23: 0.15 | E23: cm | F23: 125 | I23: =IF(H23="", D23*F23,D23*F23*H23) -> 18.75
A24: P8 | B24: Waterjet Cut | C24: Cutting Metal sheet | D24: 0.01 | E24: cm | F24: 704.92 | G24: Material - Aluminum | H24: 3 | I24: =IF($H24<>"",$D24*$F24*$H24,$D24*$F24) -> 21.1476
A25: P9 | B25: Surface Preparation for Painting | C25: Surface preparation for painting on the entire tube structure | D25: 10 | E25: m² | F25: =E13 -> 3.1067472 | I25: =IF(H25<>"",D25*F25*H25,D25*F25) -> 31.067472 | J25: =I27*$N$2 -> 47.4176
A26: P10 | B26: Paint Apply, Schultz Type Application | C26: Protective painting entire tube structure with paint (M45) | D26: 2 | E26: m² | F26: =E13 -> 3.1067472 | I26: =IF(H26="", D26*F26,D26*F26*H26) -> 6.2134944
H27: Sub Total | I27: =SUM(I17:I24) -> 47.4176 | J27: Sub Total
A29: ItemOrder | B29: Fastener | C29: Use | D29: UnitCost | E29: Size1 | F29: Unit1 | G29: Size2 | H29: Unit2 | I29: Quantity | J29: =SUM(J28) -> 0 | K29: =J29*$N$2 -> 0
I31: Sub Total
A33: ItemOrder | B33: Tooling | C33: Use | D33: UnitCost | E33: Unit | F33: Quantity | G33: PVF | H33: FracIncld | I33: Sub Total | J33: =I35*$N$2 -> 0.66666667
A34: T1 | B34: Welds - Welding Fixture | C34: Entire tube structure, Nodes of chassis | D34: 500 | E34: point | F34: 4 | G34: 3000 | H34: 1 | I34: =IFERROR(D34*F34/(G34*H34),0) -> 0.66666667
H35: Sub Total | I35: =SUM(I34) -> 0.66666667
